<?xml version="1.0"?>
<robot name="end_effector">
  <!-- 材质定义 -->
  <material name="base_color">
    <color rgba="0.8 0.8 0.5 1"/> 
  </material>
  <material name="joint_color">
    <color rgba="0.5 0.5 0.5 1"/> 
  </material>

  <!-- 底座 -->
  <link name="base_link">
    <visual>
      <geometry>
        <box size="0.5 0.2 0.1"/>
      </geometry>
      <origin xyz="0 0 0.05"/>
      <material name="base_color"/>
    </visual>
    <collision>
      <geometry>
        <box size="0.5 0.2 0.1"/>
      </geometry>
      <origin xyz="0 0 0.05"/>
    </collision>
    <inertial>
      <mass value="1.0"/>
      <inertia ixx="0.01" ixy="0" ixz="0" iyy="0.01" iyz="0" izz="0.01"/>
      <origin xyz="0 0 0.05"/>
    </inertial>
  </link>

  <!-- 左侧移动部件 -->
  <link name="left_part">
    <visual>
      <geometry>
        <box size="0.2 0.05 0.1"/>
      </geometry>
      <origin xyz="0 0 0.05"/>
      <material name="joint_color"/>
    </visual>
    <collision>
      <geometry>
        <box size="0.2 0.05 0.1"/>
      </geometry>
      <origin xyz="0 0 0.05"/>
    </collision>
    <inertial>
      <mass value="0.5"/>
      <inertia ixx="0.001" ixy="0" ixz="0" iyy="0.001" iyz="0" izz="0.001"/>
      <origin xyz="0 0 0.05"/>
    </inertial>
  </link>

  <joint name="left_part_joint" type="prismatic">
    <parent link="base_link"/>
    <child link="left_part"/>
    <origin xyz="-0.15 0 0.1"/>
    <axis xyz="1 0 0"/> <!-- 沿x轴移动 -->
    <limit lower="-0.1" upper="0.1" effort="10" velocity="0.5"/>
  </joint>

  <!-- 右侧移动部件 -->
  <link name="right_part">
    <visual>
      <geometry>
        <box size="0.2 0.05 0.1"/>
      </geometry>
      <origin xyz="0 0 0.05"/>
      <material name="joint_color"/>
    </visual>
    <collision>
      <geometry>
        <box size="0.2 0.05 0.1"/>
      </geometry>
      <origin xyz="0 0 0.05"/>
    </collision>
    <inertial>
      <mass value="0.5"/>
      <inertia ixx="0.001" ixy="0" ixz="0" iyy="0.001" iyz="0" izz="0.001"/>
      <origin xyz="0 0 0.05"/>
    </inertial>
  </link>

  <joint name="right_part_joint" type="prismatic">
    <parent link="base_link"/>
    <child link="right_part"/>
    <origin xyz="0.15 0 0.1"/>
    <axis xyz="1 0 0"/> <!-- 沿x轴移动 -->
    <limit lower="-0.1" upper="0.1" effort="10" velocity="0.5"/>
  </joint>

  <!-- Gazebo插件 -->
  <gazebo>
    <plugin name="robot_state_publisher" filename="libgazebo_ros_control.so">
      <robotNamespace>/</robotNamespace>
    </plugin>
  </gazebo>

</robot>