<?xml version="1.0"?>
<robot name="simple_arm">

  <link name="base_link">
    <visual>
      <geometry>
        <box size="0.1 0.1 0.2"/>
      </geometry>
      <material name="blue">
        <color rgba="0 0 0.8 1"/> 
      </material>
    </visual>
    <collision>
      <geometry>
        <box size="0.1 0.1 0.2"/>
      </geometry>
    </collision>
    <inertial>
      <mass value="1"/> 
      <inertia ixx="0.001" ixy="0" ixz="0" iyy="0.001" iyz="0" izz="0.001"/> 
    </inertial>
  </link>

  <link name="arm_link">
    <visual>
      <geometry>
        <cylinder radius="0.04" length="0.5"/> 
      </geometry>
      <origin xyz="0 0 0.25" rpy="0 0 0"/> 
      <material name="green">
        <color rgba="0 0.8 0 1"/>
      </material>
    </visual>
    <collision>
       <geometry>
        <cylinder radius="0.04" length="0.5"/>
       </geometry>
      <origin xyz="0 0 0.25" rpy="0 0 0"/>
    </collision>
     <inertial>
      <mass value="0.5"/>
      <origin xyz="0 0 0.25" rpy="0 0 0"/> <inertia ixx="0.001" ixy="0" ixz="0" iyy="0.001" iyz="0" izz="0.001"/>
    </inertial>
  </link>

  <joint name="base_to_arm_joint" type="revolute"> 
    <parent link="base_link"/> 
    <child link="arm_link"/>  
    <origin xyz="0 0 0.1" rpy="0 0 0"/> 
    <axis xyz="0 1 0"/> 
    <limit effort="10" velocity="1.0" lower="-1.57" upper="1.57"/> 
  </joint>

</robot>
