<?xml version="1.0" ?>

<robot name="puma560" xmlns:xacro="http://www.ros.org/wiki/xacro">

  <!-- Start GZ or Ignition depending on ROS 2 Version -->
  <xacro:arg name="is_ignition" default="true"/>

  <!-- Include Gazebo Parameters -->
  <xacro:include filename="$(find puma560_description)/urdf/puma560_robot_gazebo.xacro" />

  <!-- Include ros2_control Plugins -->
  <xacro:include filename="$(find puma560_description)/urdf/puma560_robot_ros2_control.xacro" />

  <material name="blue">
    <color rgba="0 0 0.8 0.8"/>
  </material>
  <material name="red">
    <color rgba="0.8 0 0 0.8"/>
  </material>
  <material name="green">
    <color rgba="0 0.8 0 0.8"/>
  </material>

  <xacro:macro name="default_inertial" params="mass">
        <inertial>
            <origin xyz="0 0 0" rpy="0 0 0"/>
            <mass value="${mass}" />
            <inertia ixx="1.0" ixy="0.0" ixz="0.0"
                     iyy="1.0" iyz="0.0"
                     izz="1.0" />
        </inertial>
    </xacro:macro>


  <link name="world"/>
  
  <link name="link1">
    <xacro:default_inertial mass="100.0"/>
    <visual>
      <geometry>
        <mesh filename="package://puma560_description/meshes/puma_link1.stl" scale="0.0254 0.0254 0.0254"/>
      </geometry>
      <origin rpy="0 0 1.570796325"/>
      <material name="green"/>
    </visual>
    <collision>
      <geometry>
        <mesh filename="package://puma560_description/meshes/puma_link1.stl" scale="0.0254 0.0254 0.0254"/>
      </geometry>
      <origin rpy="0 0 1.570796325"/>
    </collision>
  </link>
  <link name="link2">
    <xacro:default_inertial mass="0.1"/>
    <visual>
      <geometry>
        <mesh filename="package://puma560_description/meshes/puma_link2.stl" scale="0.0254 0.0254 0.0254"/>
      </geometry>
      <origin rpy="0 0 0" xyz="0 0 -0.1"/>
      <material name="red"/>
    </visual>
    <collision>
      <geometry>
        <mesh filename="package://puma560_description/meshes/puma_link2.stl" scale="0.0254 0.0254 0.0254"/>
      </geometry>
      <origin rpy="0 0 0" xyz="0 0 -0.1"/>
    </collision>
  </link>

  <joint name="virtual_joint" type="fixed">
    <parent link="world"/>
    <child link="link1"/>
    <origin xyz="0 0 0" rpy="0 0 0"/>
</joint> 
  <joint name="j1" type="revolute">
    <parent link="link1"/>
    <child link="link2"/>
    <origin rpy="1.570796325 0 0" xyz="0 0 0.6718"/>
    <axis xyz="0 1 0"/>
    <!-- This is descibed in child frame -->
    <limit effort="1000.0" lower="-3.14159265" upper="3.14159265" velocity="10.0"/>
  </joint>
  <link name="link3">
    <xacro:default_inertial mass="0.1"/>
    <visual>
      <geometry>
        <mesh filename="package://puma560_description/meshes/puma_link3.stl" scale="0.0254 0.0254 0.0254"/>
      </geometry>
      <origin xyz="0 0 0.1936"/>
      <material name="blue"/>
    </visual>
    <collision>
      <geometry>
        <mesh filename="package://puma560_description/meshes/puma_link3.stl" scale="0.0254 0.0254 0.0254"/>
      </geometry>
      <origin xyz="0 0 0.1936"/>
    </collision>
  </link>
  <joint name="j2" type="revolute">
    <parent link="link2"/>
    <child link="link3"/>
    <origin rpy="0 0 0" xyz="0 0 0"/>
    <axis xyz="0 0 1"/>
    <!-- This is descibed in child frame -->
    <limit effort="1000.0" lower="-1.570796325" upper="1.570796325" velocity="10.0"/>
  </joint>
  <link name="link4">
    <xacro:default_inertial mass="0.1"/>
    <visual>
      <geometry>
        <mesh filename="package://puma560_description/meshes/puma_link4.stl" scale="0.0254 0.0254 0.0254"/>
      </geometry>
      <origin rpy="0 0 0" xyz="0 0 0"/>
      <material name="green"/>
    </visual>
    <collision>
      <geometry>
        <mesh filename="package://puma560_description/meshes/puma_link4.stl" scale="0.0254 0.0254 0.0254"/>
      </geometry>
      <origin rpy="0 0 0" xyz="0 0 0"/>
    </collision>
  </link>
  <joint name="j3" type="revolute">
    <parent link="link3"/>
    <child link="link4"/>
    <origin rpy="0 0 -1.570796325" xyz="0.4318 -0.0203 0.1501"/>
    <axis xyz="0 0 1"/>
    <!-- This is descibed in child frame -->
    <limit effort="1000.0" lower="-1.570796325" upper="1.570796325" velocity="10.0"/>
  </joint>
  <link name="link5">
    <xacro:default_inertial mass="0.1"/>
    <visual>
      <geometry>
        <mesh filename="package://puma560_description/meshes/puma_link5.stl" scale="0.0254 0.0254 0.0254"/>
      </geometry>
      <origin rpy="0 0 1.570796325" xyz="0 0 0.3621"/>
      <material name="red"/>
    </visual>
    <collision>
      <geometry>
        <mesh filename="package://puma560_description/meshes/puma_link5.stl" scale="0.0254 0.0254 0.0254"/>
      </geometry>
      <origin rpy="0 0 1.570796325" xyz="0 0 0.3621"/>
    </collision>
  </link>
  <joint name="j4" type="revolute">
    <parent link="link4"/>
    <child link="link5"/>
    <origin rpy="1.570796325 0 1.570796325" xyz="0 0 0"/>
    <axis xyz="0 0 1"/>
    <limit effort="1000.0" lower="-1.570796325" upper="1.570796325" velocity="10.0"/>
  </joint>
  <link name="link6">
    <xacro:default_inertial mass="0.1"/>
    <visual>
      <geometry>
        <mesh filename="package://puma560_description/meshes/puma_link6.stl" scale="0.0254 0.0254 0.0254"/>
      </geometry>
      <origin rpy="3.14159265 0 1.570796325" xyz="0 0 0"/>
      <material name="green"/>
    </visual>
    <collision>
      <geometry>
        <mesh filename="package://puma560_description/meshes/puma_link6.stl" scale="0.0254 0.0254 0.0254"/>
      </geometry>
      <origin rpy="3.14159265 0 1.570796325" xyz="0 0 0"/>
    </collision>
  </link>
  <joint name="j5" type="revolute">
    <parent link="link5"/>
    <child link="link6"/>
    <origin rpy="1.570796325 0 0" xyz="0 0 0.4331"/>
    <axis xyz="0 0 1"/>
    <limit effort="1000.0" lower="-1.570796325" upper="1.570796325" velocity="10.0"/>
  </joint>
  <link name="link7">
    <xacro:default_inertial mass="0.1"/>
    <visual>
      <geometry>
        <mesh filename="package://puma560_description/meshes/puma_link7.stl" scale="0.0254 0.0254 0.0254"/>
      </geometry>
      <origin rpy="0 0 0" xyz="0 0 -0.010"/>
      <material name="blue"/>
    </visual>
    <collision>
      <geometry>
        <mesh filename="package://puma560_description/meshes/puma_link7.stl" scale="0.0254 0.0254 0.0254"/>
      </geometry>
      <origin rpy="0 0 0" xyz="0 0 -0.010"/>
    </collision>
  </link>
  <joint name="j6" type="revolute">
    <parent link="link6"/>
    <child link="link7"/>
    <origin rpy="-1.570796325 0 0" xyz="0 0.0558 0"/>
    <axis xyz="0 0 1"/>
    <limit effort="1000.0" lower="-1.570796325" upper="1.570796325" velocity="10.0"/>
  </joint>
</robot>
