<?xml version="1.0" encoding="utf-8"?>
<robot xmlns:xacro="http://www.ros.org/wiki/xacro" >
  <xacro:include filename="inertial_macros.xacro"/>

  <material name="white">
    <color rgba="1 1 1 1"/>
  </material>

  <material name="orange">
    <color rgba="1 0.3 0.1 1"/>
  </material>

  <material name="blue">
    <color rgba="0.2 0.2 1 1"/>
  </material>

  <material name="black">
    <color rgba="0 0 0 1"/>
  </material>
  
  <!-- BASE LINK  -->
  <link name="base_link">
    
  </link>

  <!-- base -->
  <joint name="base_joint" type="fixed">
    <parent link="base_link"/>
    <child link="base"/>
    <origin xyz="0 0 0.05"/>
  </joint>

  <link name="base">
    <visual>
      <origin xyz="0.15 0 0.075"/>
      <geometry>
        <box size="0.3 0.3 0.15"/>
      </geometry>
      <material name="white"/>
    </visual>
    <collision>
      <origin xyz="0.15 0 0.075"/>
      <geometry>
        <box size="0.3 0.3 0.15"/>
      </geometry>
    </collision>
    <xacro:inertial_box mass="0.5" x="0.3" y="0.3" z="0.15">
      <origin xyz="0.15 0 0.075" rpy="0 0 0"/>
    </xacro:inertial_box>
  </link>

  <!-- left_wheel -->

  <joint name="left_wheel_joint" type="continuous">
    <parent link="base"/>
    <child link="left_wheel"/>
    <origin xyz="0.05 0.175 0" rpy="-${pi/2} 0 0"/>
    <axis xyz="0 0 1"/>
  </joint>

  <link name="left_wheel">
    <visual>
      <geometry>
        <cylinder radius="0.05" length="0.04"/>
      </geometry>
      <material name="blue"/>
    </visual>
    <collision>
      <geometry>
        <cylinder radius="0.05" length="0.04"/>
      </geometry>
    </collision>
    <xacro:inertial_cylinder mass="0.1" length="0.04" radius="0.05">
      <origin xyz="0 0 0" rpy="0 0 0"/>
    </xacro:inertial_cylinder>
  </link>

  <!-- right_wheel -->

  <joint name="right_wheel_joint" type="continuous">
    <parent link="base"/>
    <child link="right_wheel"/>
    <origin xyz="0.05 -0.175 0" rpy="${pi/2} 0 0"/>
    <axis xyz="0 0 -1"/>
  </joint>

  <link name="right_wheel">
    <visual>
      <geometry>
        <cylinder radius="0.05" length="0.04"/>
      </geometry>
      <material name="blue"/>
    </visual>
    <collision>
      <geometry>
        <cylinder radius="0.05" length="0.04"/>
      </geometry>
    </collision>
    <xacro:inertial_cylinder mass="0.1" length="0.04" radius="0.05">
      <origin xyz="0 0 0" rpy="0 0 0"/>
    </xacro:inertial_cylinder>
  </link>

  <joint name="caster_wheel_joint" type="fixed">
    <parent link="base"/>
    <child link="caster_wheel"/>
    <origin xyz="0.24 0 0"/>
  </joint>

  <link name="caster_wheel">
    <visual>
      <geometry>
        <sphere radius="0.05"/>
      </geometry>
      <material name="black"/>
    </visual>
    <collision>
      <geometry>
        <sphere radius="0.05"/>
      </geometry>
    </collision>
    <xacro:inertial_sphere mass="0.1" radius="0.05">
      <origin xyz="0 0 0" rpy="0 0 0"/>
    </xacro:inertial_sphere>
  </link>

  <!-- arm_base -->
  <link name="arm_base_link">
    <visual>
      <geometry>
        <cylinder radius="0.02" length="0.1"/>
      </geometry>
      <material name="orange"/>
    </visual>
    <collision>
      <geometry>
        <cylinder radius="0.02" length="0.1"/>
      </geometry>
    </collision>
    <xacro:inertial_cylinder mass="0.5" length="0.1" radius="0.02">
      <origin xyz="0 0 0" rpy="0 0 0"/>
    </xacro:inertial_cylinder>
  </link>

  <joint name="arm_base_joint" type="fixed">
    <parent link="base_link"/>
    <child link="arm_base_link"/>
    <origin xyz="0.15 0 0.15" rpy="0 0 0"/>  
  </joint>

  <!-- arm_link1 -->
  <link name="arm_link1">
    <visual>
      <geometry>
        <box size="0.05 0.05 0.3"/>
      </geometry>
      <material name="black"/>
    </visual>
    <collision>
      <geometry>
        <box size="0.05 0.05 0.3"/>
      </geometry>
    </collision>
    <xacro:inertial_box mass="1.0" x="0.05" y="0.05" z="0.3">
      <origin xyz="0 0 0.15" rpy="0 0 0"/>
    </xacro:inertial_box>
  </link>

  <joint name="arm_joint1" type="revolute">
    <parent link="arm_base_link"/>
    <child link="arm_link1"/>
    <origin xyz="0 0 0.05" rpy="0 0 0"/>  
    <axis xyz="0 1 0"/>  
    <limit lower="-1.57" upper="1.57" effort="10" velocity="1.0"/>
  </joint>

  <!-- arm_link2 -->
  <link name="arm_link2">
    <visual>
      <geometry>
        <box size="0.3 0.05 0.05"/>
      </geometry>
      <material name="blue"/>
    </visual>
    <collision>
      <geometry>
        <box size="0.3 0.05 0.05"/>
      </geometry>
    </collision>
    <xacro:inertial_box mass="0.8" x="0.3" y="0.05" z="0.05">
      <origin xyz="0.15 0 0" rpy="0 0 0"/>
    </xacro:inertial_box>
  </link>

  <joint name="arm_joint2" type="revolute">
    <parent link="arm_link1"/>
    <child link="arm_link2"/>
    <origin xyz="0 0 0.3" rpy="0 0 0"/>
    <axis xyz="0 0 1"/>
    <limit lower="-3.14" upper="3.14" effort="10" velocity="1.0"/>
  </joint>

  <gazebo reference="caster_wheel">
    <material>Gazebo/Black</material>
    <mu1 value="0.001"/>
    <mu2 value="0.001"/>
  </gazebo>
  
</robot>