<?xml version="1.0"?>
<robot name="wmm_robot">
    <link name="base_link">
        <visual>
            <geometry>
                <box size="0.4 0.4 0.2"/>
            </geometry>
            <material name="grey">
                <color rgba="0.5 0.5 0.5 1"/>
            </material>
        </visual>
        <collision>
            <geometry>
                <box size="0.4 0.4 0.2"/>
            </geometry>
        </collision>
        <inertial>
            <mass value="50"/>
            <inertia ixx="0.8333" ixy="0" ixz="0" iyy="0.8333" iyz="0" izz="1.3333"/>
        </inertial>
    </link>

    <link name="link_1">
        <visual>
            <geometry>
                <cylinder radius="0.05" length="0.5"/>
            </geometry>
            <origin xyz="0 0 0.25" rpy="0 0 0"/>
            <material name="blue">
                <color rgba="0.1 0.1 0.8 1"/>
            </material>
        </visual>
        <collision>
            <geometry>
                <cylinder radius="0.05" length="0.5"/>
            </geometry>
            <origin xyz="0 0 0.25" rpy="0 0 0"/>
        </collision>
        <inertial>
            <mass value="10"/>
            <origin xyz="0 0 0.25" rpy="0 0 0"/>
            <inertia ixx="0.2146" ixy="0" ixz="0" iyy="0.2146" iyz="0" izz="0.0125"/>
        </inertial>
    </link>

    <link name="link_2">
        <visual>
            <geometry>
                <cylinder radius="0.05" length="0.5"/>
            </geometry>
            <origin xyz="0 0 0.25" rpy="0 0 0"/>
            <material name="green">
                <color rgba="0.1 0.8 0.1 1"/>
            </material>
        </visual>
        <collision>
            <geometry>
                <cylinder radius="0.05" length="0.5"/>
            </geometry>
            <origin xyz="0 0 0.25" rpy="0 0 0"/>
        </collision>
        <inertial>
            <mass value="10"/>
            <origin xyz="0 0 0.25" rpy="0 0 0"/>
            <inertia ixx="0.2146" ixy="0" ixz="0" iyy="0.2146" iyz="0" izz="0.0125"/>
        </inertial>
    </link>

    <joint name="wmm_joint_1" type="revolute">
        <parent link="base_link"/>
        <child link="link_1"/>
        <origin xyz="0 0 0.1" rpy="0 0 0"/>
        <axis xyz="0 0 1"/>
        <limit lower="-3.14" upper="3.14" effort="100" velocity="1.0"/>
    </joint>

    <joint name="wmm_joint_2" type="revolute">
        <parent link="link_1"/>
        <child link="link_2"/>
        <origin xyz="0 0 0.5" rpy="0 0 0"/>
        <axis xyz="0 1 0"/>
        <limit lower="0" upper="0.78" effort="100" velocity="1.0"/>
    </joint>

    <link name="actual_end_effector_link">
        <visual>
            <geometry>
                <box size="0.05 0.05 0.05"/>
            </geometry>
            <material name="red">
                <color rgba="0.8 0.1 0.1 1"/>
            </material>
        </visual>
        <collision>
            <geometry>
                <box size="0.05 0.05 0.05"/>
            </geometry>
        </collision>
        <inertial>
            <mass value="5"/>
            <inertia ixx="0.0002083" ixy="0" ixz="0" iyy="0.0002083" iyz="0" izz="0.0002083"/>
        </inertial>
    </link>

    <joint name="wmm_gripper_joint" type="fixed">
        <parent link="link_2"/>
        <child link="actual_end_effector_link"/>
        <origin xyz="0 0 0.5" rpy="0 0 0"/>
    </joint>

    <gazebo>
        <plugin name="gazebo_ros_joint_state_publisher" filename="libgazebo_ros_joint_state_publisher.so">
            <ros>
                <namespace>/</namespace>
                <remapping>~/out:=joint_states</remapping>
            </ros>
            <update_rate>100</update_rate>
            <joint_name>wmm_joint_1</joint_name>
            <joint_name>wmm_joint_2</joint_name>
        </plugin>
    </gazebo>
</robot>